<?xml version="1.0" encoding="UTF-8"?>
<!-- Generated by org.testng.reporters.JUnitXMLReporter -->
<testsuite hostname="ws-tall-71" name="myTest" tests="17" failures="15" timestamp="29 Dec 2015 15:11:01 GMT" time="143.098" errors="0">
  <testcase name="deviceList" time="2.193" classname="com.perfectomobile.BuildDevicesList"/>
  <testcase name="testDevices" time="1.742" classname="com.perfectomobile.NativeExe">
    <failure type="java.lang.AssertionError" message="Test Ended with error">
      <![CDATA[java.lang.AssertionError: Test Ended with error
	at com.perfectomobile.NativeExe.testDevices(NativeExe.java:110)
	at java.util.concurrent.FutureTask.run(Unknown Source)
	at java.util.concurrent.Executors$RunnableAdapter.call(Unknown Source)
	at java.util.concurrent.FutureTask.run(Unknown Source)
	at java.util.concurrent.ThreadPoolExecutor.runWorker(Unknown Source)
	at java.util.concurrent.ThreadPoolExecutor$Worker.run(Unknown Source)
	at java.lang.Thread.run(Unknown Source)
... Removed 10 stack frames]]>
    </failure>
  </testcase> <!-- testDevices -->
  <testcase name="testDevices" time="44.796" classname="com.perfectomobile.NativeExe">
    <failure type="java.lang.AssertionError" message="Test Ended with error">
      <![CDATA[java.lang.AssertionError: Test Ended with error
	at com.perfectomobile.NativeExe.testDevices(NativeExe.java:110)
	at java.util.concurrent.FutureTask.run(Unknown Source)
	at java.util.concurrent.Executors$RunnableAdapter.call(Unknown Source)
	at java.util.concurrent.FutureTask.run(Unknown Source)
	at java.util.concurrent.ThreadPoolExecutor.runWorker(Unknown Source)
	at java.util.concurrent.ThreadPoolExecutor$Worker.run(Unknown Source)
	at java.lang.Thread.run(Unknown Source)
... Removed 10 stack frames]]>
    </failure>
  </testcase> <!-- testDevices -->
  <testcase name="testDevices" time="62.727" classname="com.perfectomobile.NativeExe"/>
  <testcase name="testDevices" time="63.072" classname="com.perfectomobile.NativeExe">
    <failure type="java.lang.AssertionError" message="Test Ended with error">
      <![CDATA[java.lang.AssertionError: Test Ended with error
	at com.perfectomobile.NativeExe.testDevices(NativeExe.java:110)
	at java.util.concurrent.FutureTask.run(Unknown Source)
	at java.util.concurrent.Executors$RunnableAdapter.call(Unknown Source)
	at java.util.concurrent.FutureTask.run(Unknown Source)
	at java.util.concurrent.ThreadPoolExecutor.runWorker(Unknown Source)
	at java.util.concurrent.ThreadPoolExecutor$Worker.run(Unknown Source)
	at java.lang.Thread.run(Unknown Source)
... Removed 10 stack frames]]>
    </failure>
  </testcase> <!-- testDevices -->
  <testcase name="testDevices" time="63.317" classname="com.perfectomobile.NativeExe">
    <failure type="java.lang.AssertionError" message="Test Ended with error">
      <![CDATA[java.lang.AssertionError: Test Ended with error
	at com.perfectomobile.NativeExe.testDevices(NativeExe.java:110)
	at java.util.concurrent.FutureTask.run(Unknown Source)
	at java.util.concurrent.Executors$RunnableAdapter.call(Unknown Source)
	at java.util.concurrent.FutureTask.run(Unknown Source)
	at java.util.concurrent.ThreadPoolExecutor.runWorker(Unknown Source)
	at java.util.concurrent.ThreadPoolExecutor$Worker.run(Unknown Source)
	at java.lang.Thread.run(Unknown Source)
... Removed 10 stack frames]]>
    </failure>
  </testcase> <!-- testDevices -->
  <testcase name="testDevices" time="64.074" classname="com.perfectomobile.NativeExe">
    <failure type="java.lang.AssertionError" message="Test Ended with error">
      <![CDATA[java.lang.AssertionError: Test Ended with error
	at com.perfectomobile.NativeExe.testDevices(NativeExe.java:110)
	at java.util.concurrent.FutureTask.run(Unknown Source)
	at java.util.concurrent.Executors$RunnableAdapter.call(Unknown Source)
	at java.util.concurrent.FutureTask.run(Unknown Source)
	at java.util.concurrent.ThreadPoolExecutor.runWorker(Unknown Source)
	at java.util.concurrent.ThreadPoolExecutor$Worker.run(Unknown Source)
	at java.lang.Thread.run(Unknown Source)
... Removed 10 stack frames]]>
    </failure>
  </testcase> <!-- testDevices -->
  <testcase name="testDevices" time="72.079" classname="com.perfectomobile.NativeExe">
    <failure type="java.lang.AssertionError" message="Test Ended with error">
      <![CDATA[java.lang.AssertionError: Test Ended with error
	at com.perfectomobile.NativeExe.testDevices(NativeExe.java:110)
	at java.util.concurrent.FutureTask.run(Unknown Source)
	at java.util.concurrent.Executors$RunnableAdapter.call(Unknown Source)
	at java.util.concurrent.FutureTask.run(Unknown Source)
	at java.util.concurrent.ThreadPoolExecutor.runWorker(Unknown Source)
	at java.util.concurrent.ThreadPoolExecutor$Worker.run(Unknown Source)
	at java.lang.Thread.run(Unknown Source)
... Removed 10 stack frames]]>
    </failure>
  </testcase> <!-- testDevices -->
  <testcase name="testDevices" time="76.875" classname="com.perfectomobile.NativeExe">
    <failure type="java.lang.AssertionError" message="Test Ended with error">
      <![CDATA[java.lang.AssertionError: Test Ended with error
	at com.perfectomobile.NativeExe.testDevices(NativeExe.java:110)
	at java.util.concurrent.FutureTask.run(Unknown Source)
	at java.util.concurrent.Executors$RunnableAdapter.call(Unknown Source)
	at java.util.concurrent.FutureTask.run(Unknown Source)
	at java.util.concurrent.ThreadPoolExecutor.runWorker(Unknown Source)
	at java.util.concurrent.ThreadPoolExecutor$Worker.run(Unknown Source)
	at java.lang.Thread.run(Unknown Source)
... Removed 10 stack frames]]>
    </failure>
  </testcase> <!-- testDevices -->
  <testcase name="testDevices" time="0.687" classname="com.perfectomobile.DomExe">
    <failure type="java.lang.AssertionError" message="Test Ended with error">
      <![CDATA[java.lang.AssertionError: Test Ended with error
	at com.perfectomobile.DomExe.testDevices(DomExe.java:108)
	at java.util.concurrent.FutureTask.run(Unknown Source)
	at java.util.concurrent.Executors$RunnableAdapter.call(Unknown Source)
	at java.util.concurrent.FutureTask.run(Unknown Source)
	at java.util.concurrent.ThreadPoolExecutor.runWorker(Unknown Source)
	at java.util.concurrent.ThreadPoolExecutor$Worker.run(Unknown Source)
	at java.lang.Thread.run(Unknown Source)
... Removed 10 stack frames]]>
    </failure>
  </testcase> <!-- testDevices -->
  <testcase name="testDevices" time="23.146" classname="com.perfectomobile.DomExe">
    <failure type="java.lang.AssertionError" message="Test Ended with error">
      <![CDATA[java.lang.AssertionError: Test Ended with error
	at com.perfectomobile.DomExe.testDevices(DomExe.java:108)
	at java.util.concurrent.FutureTask.run(Unknown Source)
	at java.util.concurrent.Executors$RunnableAdapter.call(Unknown Source)
	at java.util.concurrent.FutureTask.run(Unknown Source)
	at java.util.concurrent.ThreadPoolExecutor.runWorker(Unknown Source)
	at java.util.concurrent.ThreadPoolExecutor$Worker.run(Unknown Source)
	at java.lang.Thread.run(Unknown Source)
... Removed 10 stack frames]]>
    </failure>
  </testcase> <!-- testDevices -->
  <testcase name="testDevices" time="24.76" classname="com.perfectomobile.DomExe">
    <failure type="java.lang.AssertionError" message="Test Ended with error">
      <![CDATA[java.lang.AssertionError: Test Ended with error
	at com.perfectomobile.DomExe.testDevices(DomExe.java:108)
	at java.util.concurrent.FutureTask.run(Unknown Source)
	at java.util.concurrent.Executors$RunnableAdapter.call(Unknown Source)
	at java.util.concurrent.FutureTask.run(Unknown Source)
	at java.util.concurrent.ThreadPoolExecutor.runWorker(Unknown Source)
	at java.util.concurrent.ThreadPoolExecutor$Worker.run(Unknown Source)
	at java.lang.Thread.run(Unknown Source)
... Removed 10 stack frames]]>
    </failure>
  </testcase> <!-- testDevices -->
  <testcase name="testDevices" time="27.458" classname="com.perfectomobile.DomExe">
    <failure type="java.lang.AssertionError" message="Test Ended with error">
      <![CDATA[java.lang.AssertionError: Test Ended with error
	at com.perfectomobile.DomExe.testDevices(DomExe.java:108)
	at java.util.concurrent.FutureTask.run(Unknown Source)
	at java.util.concurrent.Executors$RunnableAdapter.call(Unknown Source)
	at java.util.concurrent.FutureTask.run(Unknown Source)
	at java.util.concurrent.ThreadPoolExecutor.runWorker(Unknown Source)
	at java.util.concurrent.ThreadPoolExecutor$Worker.run(Unknown Source)
	at java.lang.Thread.run(Unknown Source)
... Removed 10 stack frames]]>
    </failure>
  </testcase> <!-- testDevices -->
  <testcase name="testDevices" time="32.218" classname="com.perfectomobile.DomExe">
    <failure type="java.lang.AssertionError" message="Test Ended with error">
      <![CDATA[java.lang.AssertionError: Test Ended with error
	at com.perfectomobile.DomExe.testDevices(DomExe.java:108)
	at java.util.concurrent.FutureTask.run(Unknown Source)
	at java.util.concurrent.Executors$RunnableAdapter.call(Unknown Source)
	at java.util.concurrent.FutureTask.run(Unknown Source)
	at java.util.concurrent.ThreadPoolExecutor.runWorker(Unknown Source)
	at java.util.concurrent.ThreadPoolExecutor$Worker.run(Unknown Source)
	at java.lang.Thread.run(Unknown Source)
... Removed 10 stack frames]]>
    </failure>
  </testcase> <!-- testDevices -->
  <testcase name="testDevices" time="34.277" classname="com.perfectomobile.DomExe">
    <failure type="java.lang.AssertionError" message="Test Ended with error">
      <![CDATA[java.lang.AssertionError: Test Ended with error
	at com.perfectomobile.DomExe.testDevices(DomExe.java:108)
	at java.util.concurrent.FutureTask.run(Unknown Source)
	at java.util.concurrent.Executors$RunnableAdapter.call(Unknown Source)
	at java.util.concurrent.FutureTask.run(Unknown Source)
	at java.util.concurrent.ThreadPoolExecutor.runWorker(Unknown Source)
	at java.util.concurrent.ThreadPoolExecutor$Worker.run(Unknown Source)
	at java.lang.Thread.run(Unknown Source)
... Removed 10 stack frames]]>
    </failure>
  </testcase> <!-- testDevices -->
  <testcase name="testDevices" time="36.59" classname="com.perfectomobile.DomExe">
    <failure type="java.lang.AssertionError" message="Test Ended with error">
      <![CDATA[java.lang.AssertionError: Test Ended with error
	at com.perfectomobile.DomExe.testDevices(DomExe.java:108)
	at java.util.concurrent.FutureTask.run(Unknown Source)
	at java.util.concurrent.Executors$RunnableAdapter.call(Unknown Source)
	at java.util.concurrent.FutureTask.run(Unknown Source)
	at java.util.concurrent.ThreadPoolExecutor.runWorker(Unknown Source)
	at java.util.concurrent.ThreadPoolExecutor$Worker.run(Unknown Source)
	at java.lang.Thread.run(Unknown Source)
... Removed 10 stack frames]]>
    </failure>
  </testcase> <!-- testDevices -->
  <testcase name="testDevices" time="63.979" classname="com.perfectomobile.DomExe">
    <failure type="java.lang.AssertionError" message="Test Ended with error">
      <![CDATA[java.lang.AssertionError: Test Ended with error
	at com.perfectomobile.DomExe.testDevices(DomExe.java:108)
	at java.util.concurrent.FutureTask.run(Unknown Source)
	at java.util.concurrent.Executors$RunnableAdapter.call(Unknown Source)
	at java.util.concurrent.FutureTask.run(Unknown Source)
	at java.util.concurrent.ThreadPoolExecutor.runWorker(Unknown Source)
	at java.util.concurrent.ThreadPoolExecutor$Worker.run(Unknown Source)
	at java.lang.Thread.run(Unknown Source)
... Removed 10 stack frames]]>
    </failure>
  </testcase> <!-- testDevices -->
</testsuite> <!-- myTest -->
